### Существует проблема с блоком catch в предоставленном вами блоке кода. Блок catch указывает, что он будет перехватывать исключение ArithmeticException, которое является правильным, если возникает ошибка деления на ноль. Однако на самом деле выдается ошибка ArrayIndexOutOfBoundsException при попытке получить доступ к элементу intArray[8], поскольку в intArray нет по крайней мере 9 элементов.

### Чтобы исправить это, вы можете перехватить правильный тип исключения (ArrayIndexOutOfBoundsException) в блоке catch, а затем обработать его соответствующим образом:
```Java
try {
   int d = 0;
   double catchedRes1 = intArray[8] / d;
   System.out.println("catchedRes1 = " + catchedRes1);
} catch (ArrayIndexOutOfBoundsException e) {
   System.out.println("Invalid array index: " + e);
} catch (ArithmeticException e) {
   System.out.println("Catching exception: " + e);
}
```

### Теперь, если при обращении к intArray[8] возникает исключение `ArrayIndexOutOfBoundsException`, первый блок catch будет выполнен и выведет сообщение об ошибке. Если возникает исключение `ArithmeticException`, второй блок catch будет выполнен и выведет другое сообщение об ошибке.

### Таким образом, программа может корректно обрабатывать обе потенциальные ошибки и продолжать выполнение без сбоев.