## Вот реализация статического метода в JavaScript, которая соответствует заявленным требованиям:
```JavaScript
class WrongPasswordException extends Error {
  constructor(message = 'Wrong password') {
    super(message);
    this.name = 'WrongPasswordException';
  }
}

class WrongLoginException extends Error {
  constructor(message = 'Wrong login') {
    super(message);
    this.name = 'WrongLoginException';
  }
}

function validateCredentials(login, password, confirmPassword) {
  try {
    const loginRegex = /^[a-z0-9_]{1,20}$/i;
    const passwordRegex = /^[a-z0-9_]{1,20}$/i;
    if (!loginRegex.test(login)) {
      throw new WrongLoginException();
    }
    if (!passwordRegex.test(password) || password !== confirmPassword) {
      throw new WrongPasswordException();
    }
    return true;
  } catch (e) {
    console.error(e);
    return false;
  }
}
```
## Этот код определяет два пользовательских класса для исключений `WrongPasswordException` и `Wrong LoginException`, а также функцию `ValidateCredentials`, которая принимает `login`, `password` и `confirmPassword` в качестве аргументов.

## Сначала функция проверяет, является ли `login` допустимым, используя регулярное выражение, чтобы сопоставить его с требуемым шаблоном. Если "login" не соответствует шаблону, функция выдает "Неправильное исключение LoginException".

## Далее функция проверяет, соответствуют ли "пароль" и "подтвердить пароль" тому же шаблону, что и "логин", и равны ли они друг другу. Если какое-либо из условий не выполняется, функция выдает исключение `WrongPasswordException`.

## Если и "логин", и "пароль" действительны, функция возвращает `true`. Если генерируется исключение, функция перехватывает его, регистрирует в консоли и возвращает `false`.

## Обратите внимание, что блок multi-catch не используется, поскольку пользовательские классы исключений расширяют встроенный класс `Error`, поэтому они могут быть перехвачены одним блоком `catch`, который перехвачивает все экземпляры `Error`.